<?xml version="1.0" ?>
<robot name="adeept_5dof_wall">

  <material name="darkblue"><color rgba="0.15 0.15 0.35 1.0"/></material>
  <material name="grey"><color rgba="0.5 0.5 0.5 1.0"/></material>
  <material name="orange"><color rgba="0.95 0.6 0.1 1.0"/></material>
  <material name="green"><color rgba="0.1 0.75 0.5 1.0"/></material>
  <material name="white"><color rgba="0.9 0.9 0.9 1.0"/></material>
  <material name="wall"><color rgba="0.35 0.35 0.42 1.0"/></material>

  <!-- WAND -->
  <link name="wall">
    <visual><geometry><box size="0.18 0.005 0.18"/></geometry>
      <origin xyz="0 0 0.10"/><material name="wall"/></visual>
  </link>

  <!-- ======== BASE ======== -->

  <link name="base_link_l">
    <visual><geometry><box size="0.100 0.100 0.015"/></geometry>
      <origin xyz="0 0 0.0075"/><material name="darkblue"/></visual>
    <visual><geometry><cylinder radius="0.037" length="0.003"/></geometry>
      <origin xyz="0 0 0.0165"/><material name="grey"/></visual>
    <collision><geometry><box size="0.100 0.100 0.018"/></geometry><origin xyz="0 0 0.009"/></collision>
    <inertial><mass value="0.3"/><origin xyz="0 0 0.009"/>
      <inertia ixx="0.001" ixy="0" ixz="0" iyy="0.001" iyz="0" izz="0.001"/></inertial>
  </link>
  <joint name="base_to_wall_l" type="fixed">
    <parent link="wall"/><child link="base_link_l"/>
    <origin xyz="0 0.0025 0.14" rpy="-1.5708 1.5708 0"/>
  </joint>

  <link name="base_link_r">
    <visual><geometry><box size="0.100 0.100 0.015"/></geometry>
      <origin xyz="0 0 0.0075"/><material name="darkblue"/></visual>
    <visual><geometry><cylinder radius="0.037" length="0.003"/></geometry>
      <origin xyz="0 0 0.0165"/><material name="grey"/></visual>
    <collision><geometry><box size="0.100 0.100 0.018"/></geometry><origin xyz="0 0 0.009"/></collision>
    <inertial><mass value="0.3"/><origin xyz="0 0 0.009"/>
      <inertia ixx="0.001" ixy="0" ixz="0" iyy="0.001" iyz="0" izz="0.001"/></inertial>
  </link>
  <joint name="base_to_wall_r" type="fixed">
    <parent link="wall"/><child link="base_link_r"/>
    <origin xyz="0 -0.0025 0.14" rpy="1.5708 1.5708 0"/>
  </joint>

  <!-- ======== BASE JOINT (turntable) ======== -->

  <link name="turntable_l">
    <visual><geometry><cylinder radius="0.031" length="0.008"/></geometry>
      <origin xyz="0 0 0.004"/><material name="grey"/></visual>
    <collision><geometry><cylinder radius="0.032" length="0.008"/></geometry><origin xyz="0 0 0.004"/></collision>
    <inertial><mass value="0.05"/><origin xyz="0 0 0.004"/>
      <inertia ixx="0.0001" ixy="0" ixz="0" iyy="0.0001" iyz="0" izz="0.0001"/></inertial>
  </link>
  <joint name="base_joint_l" type="revolute">
    <parent link="base_link_l"/><child link="turntable_l"/>
    <origin xyz="0 0 0.018"/><axis xyz="0 0 1"/>
    <limit lower="-1.5708" upper="1.5708" effort="10" velocity="1.0"/>
  </joint>

  <link name="turntable_r">
    <visual><geometry><cylinder radius="0.031" length="0.008"/></geometry>
      <origin xyz="0 0 0.004"/><material name="grey"/></visual>
    <collision><geometry><cylinder radius="0.032" length="0.008"/></geometry><origin xyz="0 0 0.004"/></collision>
    <inertial><mass value="0.05"/><origin xyz="0 0 0.004"/>
      <inertia ixx="0.0001" ixy="0" ixz="0" iyy="0.0001" iyz="0" izz="0.0001"/></inertial>
  </link>
  <joint name="base_joint_r" type="revolute">
    <parent link="base_link_r"/><child link="turntable_r"/>
    <origin xyz="0 0 0.018"/><axis xyz="0 0 -1"/>
    <limit lower="-1.5708" upper="1.5708" effort="10" velocity="1.0"/>
  </joint>

  <!-- ======== SHOULDER BRACKET (fixed) ======== -->

  <link name="shoulder_bracket_l">
    <visual><geometry><box size="0.003 0.035 0.060"/></geometry>
      <origin xyz="-0.020 0 0.030"/><material name="darkblue"/></visual>
    <visual><geometry><box size="0.003 0.035 0.060"/></geometry>
      <origin xyz="0.020 0 0.030"/><material name="darkblue"/></visual>
    <visual><geometry><box size="0.043 0.003 0.036"/></geometry>
      <origin xyz="0 -0.0175 0.018"/><material name="darkblue"/></visual>
    <visual><geometry><box size="0.023 0.040 0.012"/></geometry>
      <origin xyz="0 0 0.060"/><material name="white"/></visual>
    <visual><geometry><cylinder radius="0.0025" length="0.045"/></geometry>
      <origin xyz="0 0 0.060" rpy="0 1.5708 0"/><material name="orange"/></visual>
    <collision><geometry><box size="0.045 0.040 0.072"/></geometry><origin xyz="0 0 0.036"/></collision>
    <inertial><mass value="0.12"/><origin xyz="0 0 0.036"/>
      <inertia ixx="0.0002" ixy="0" ixz="0" iyy="0.0002" iyz="0" izz="0.0002"/></inertial>
  </link>
  <joint name="shoulder_bracket_joint_l" type="fixed">
    <parent link="turntable_l"/><child link="shoulder_bracket_l"/>
    <origin xyz="0 0 0.008"/>
  </joint>

  <link name="shoulder_bracket_r">
    <visual><geometry><box size="0.003 0.035 0.060"/></geometry>
      <origin xyz="-0.020 0 0.030"/><material name="darkblue"/></visual>
    <visual><geometry><box size="0.003 0.035 0.060"/></geometry>
      <origin xyz="0.020 0 0.030"/><material name="darkblue"/></visual>
    <visual><geometry><box size="0.043 0.003 0.036"/></geometry>
      <origin xyz="0 -0.0175 0.018"/><material name="darkblue"/></visual>
    <visual><geometry><box size="0.023 0.040 0.012"/></geometry>
      <origin xyz="0 0 0.060"/><material name="white"/></visual>
    <visual><geometry><cylinder radius="0.0025" length="0.045"/></geometry>
      <origin xyz="0 0 0.060" rpy="0 1.5708 0"/><material name="orange"/></visual>
    <collision><geometry><box size="0.045 0.040 0.072"/></geometry><origin xyz="0 0 0.036"/></collision>
    <inertial><mass value="0.12"/><origin xyz="0 0 0.036"/>
      <inertia ixx="0.0002" ixy="0" ixz="0" iyy="0.0002" iyz="0" izz="0.0002"/></inertial>
  </link>
  <joint name="shoulder_bracket_joint_r" type="fixed">
    <parent link="turntable_r"/><child link="shoulder_bracket_r"/>
    <origin xyz="0 0 0.008"/>
  </joint>

  <!-- ======== SHOULDER JOINT (upper arm) ======== -->

  <link name="upper_arm_l">
    <visual><geometry><box size="0.003 0.035 0.105"/></geometry>
      <origin xyz="-0.0175 0 0.0525"/><material name="darkblue"/></visual>
    <visual><geometry><box size="0.003 0.035 0.105"/></geometry>
      <origin xyz="0.0175 0 0.0525"/><material name="darkblue"/></visual>
    <visual><geometry><cylinder radius="0.0015" length="0.032"/></geometry>
      <origin xyz="0 0.01225 0.016" rpy="0 1.5708 0"/><material name="grey"/></visual>
    <visual><geometry><cylinder radius="0.0015" length="0.032"/></geometry>
      <origin xyz="0 -0.01225 0.016" rpy="0 1.5708 0"/><material name="grey"/></visual>
    <visual><geometry><box size="0.023 0.040 0.012"/></geometry>
      <origin xyz="0 0 0.105"/><material name="white"/></visual>
    <visual><geometry><cylinder radius="0.0025" length="0.040"/></geometry>
      <origin xyz="0 0 0.105" rpy="0 1.5708 0"/><material name="orange"/></visual>
    <collision><geometry><box size="0.038 0.040 0.118"/></geometry><origin xyz="0 0 0.059"/></collision>
    <inertial><mass value="0.12"/><origin xyz="0 0 0.059"/>
      <inertia ixx="0.0003" ixy="0" ixz="0" iyy="0.0003" iyz="0" izz="0.0001"/></inertial>
  </link>
  <joint name="shoulder_joint_l" type="revolute">
    <parent link="shoulder_bracket_l"/><child link="upper_arm_l"/>
    <origin xyz="0 0 0.060"/><axis xyz="1 0 0"/>
    <limit lower="-0.0873" upper="1.3963" effort="10" velocity="1.0"/>
  </joint>

  <link name="upper_arm_r">
    <visual><geometry><box size="0.003 0.035 0.105"/></geometry>
      <origin xyz="-0.0175 0 0.0525"/><material name="darkblue"/></visual>
    <visual><geometry><box size="0.003 0.035 0.105"/></geometry>
      <origin xyz="0.0175 0 0.0525"/><material name="darkblue"/></visual>
    <visual><geometry><cylinder radius="0.0015" length="0.032"/></geometry>
      <origin xyz="0 0.01225 0.016" rpy="0 1.5708 0"/><material name="grey"/></visual>
    <visual><geometry><cylinder radius="0.0015" length="0.032"/></geometry>
      <origin xyz="0 -0.01225 0.016" rpy="0 1.5708 0"/><material name="grey"/></visual>
    <visual><geometry><box size="0.023 0.040 0.012"/></geometry>
      <origin xyz="0 0 0.105"/><material name="white"/></visual>
    <visual><geometry><cylinder radius="0.0025" length="0.040"/></geometry>
      <origin xyz="0 0 0.105" rpy="0 1.5708 0"/><material name="orange"/></visual>
    <collision><geometry><box size="0.038 0.040 0.118"/></geometry><origin xyz="0 0 0.059"/></collision>
    <inertial><mass value="0.12"/><origin xyz="0 0 0.059"/>
      <inertia ixx="0.0003" ixy="0" ixz="0" iyy="0.0003" iyz="0" izz="0.0001"/></inertial>
  </link>
  <joint name="shoulder_joint_r" type="revolute">
    <parent link="shoulder_bracket_r"/><child link="upper_arm_r"/>
    <origin xyz="0 0 0.060"/><axis xyz="-1 0 0"/>
    <limit lower="-0.0873" upper="1.3963" effort="10" velocity="1.0"/>
  </joint>

  <!-- ======== ELBOW JOINT (forearm) ======== -->

  <link name="forearm_l">
    <visual><geometry><box size="0.003 0.030 0.095"/></geometry>
      <origin xyz="-0.015 0 0.0475"/><material name="darkblue"/></visual>
    <visual><geometry><box size="0.003 0.030 0.095"/></geometry>
      <origin xyz="0.015 0 0.0475"/><material name="darkblue"/></visual>
    <visual><geometry><cylinder radius="0.0015" length="0.027"/></geometry>
      <origin xyz="0 0.0105 0.014" rpy="0 1.5708 0"/><material name="grey"/></visual>
    <visual><geometry><cylinder radius="0.0015" length="0.027"/></geometry>
      <origin xyz="0 -0.0105 0.014" rpy="0 1.5708 0"/><material name="grey"/></visual>
    <visual><geometry><box size="0.023 0.040 0.012"/></geometry>
      <origin xyz="0 0 0.095"/><material name="white"/></visual>
    <visual><geometry><cylinder radius="0.002" length="0.035"/></geometry>
      <origin xyz="0 0 0.095" rpy="0 1.5708 0"/><material name="orange"/></visual>
    <collision><geometry><box size="0.033 0.035 0.108"/></geometry><origin xyz="0 0 0.054"/></collision>
    <inertial><mass value="0.10"/><origin xyz="0 0 0.054"/>
      <inertia ixx="0.0002" ixy="0" ixz="0" iyy="0.0002" iyz="0" izz="0.00008"/></inertial>
  </link>
  <joint name="elbow_joint_l" type="revolute">
    <parent link="upper_arm_l"/><child link="forearm_l"/>
    <origin xyz="0 0 0.105"/><axis xyz="1 0 0"/>
    <limit lower="-0.0873" upper="1.4835" effort="10" velocity="1.0"/>
  </joint>

  <link name="forearm_r">
    <visual><geometry><box size="0.003 0.030 0.095"/></geometry>
      <origin xyz="-0.015 0 0.0475"/><material name="darkblue"/></visual>
    <visual><geometry><box size="0.003 0.030 0.095"/></geometry>
      <origin xyz="0.015 0 0.0475"/><material name="darkblue"/></visual>
    <visual><geometry><cylinder radius="0.0015" length="0.027"/></geometry>
      <origin xyz="0 0.0105 0.014" rpy="0 1.5708 0"/><material name="grey"/></visual>
    <visual><geometry><cylinder radius="0.0015" length="0.027"/></geometry>
      <origin xyz="0 -0.0105 0.014" rpy="0 1.5708 0"/><material name="grey"/></visual>
    <visual><geometry><box size="0.023 0.040 0.012"/></geometry>
      <origin xyz="0 0 0.095"/><material name="white"/></visual>
    <visual><geometry><cylinder radius="0.002" length="0.035"/></geometry>
      <origin xyz="0 0 0.095" rpy="0 1.5708 0"/><material name="orange"/></visual>
    <collision><geometry><box size="0.033 0.035 0.108"/></geometry><origin xyz="0 0 0.054"/></collision>
    <inertial><mass value="0.10"/><origin xyz="0 0 0.054"/>
      <inertia ixx="0.0002" ixy="0" ixz="0" iyy="0.0002" iyz="0" izz="0.00008"/></inertial>
  </link>
  <joint name="elbow_joint_r" type="revolute">
    <parent link="upper_arm_r"/><child link="forearm_r"/>
    <origin xyz="0 0 0.105"/><axis xyz="-1 0 0"/>
    <limit lower="-0.0873" upper="1.4835" effort="10" velocity="1.0"/>
  </joint>

  <!-- ======== WRIST JOINT ======== -->

  <link name="wrist_l">
    <visual><geometry><box size="0.025 0.025 0.030"/></geometry>
      <origin xyz="0 0 0.015"/><material name="darkblue"/></visual>
    <visual><geometry><box size="0.030 0.025 0.015"/></geometry>
      <origin xyz="0 0 0.0375"/><material name="darkblue"/></visual>
    <collision><geometry><box size="0.030 0.025 0.045"/></geometry><origin xyz="0 0 0.0225"/></collision>
    <inertial><mass value="0.05"/><origin xyz="0 0 0.0225"/>
      <inertia ixx="0.00005" ixy="0" ixz="0" iyy="0.00005" iyz="0" izz="0.00005"/></inertial>
  </link>
  <joint name="wrist_joint_l" type="revolute">
    <parent link="forearm_l"/><child link="wrist_l"/>
    <origin xyz="0 0 0.095"/><axis xyz="0 0 1"/>
    <limit lower="-1.5708" upper="1.5708" effort="5" velocity="1.0"/>
  </joint>

  <link name="wrist_r">
    <visual><geometry><box size="0.025 0.025 0.030"/></geometry>
      <origin xyz="0 0 0.015"/><material name="darkblue"/></visual>
    <visual><geometry><box size="0.030 0.025 0.015"/></geometry>
      <origin xyz="0 0 0.0375"/><material name="darkblue"/></visual>
    <collision><geometry><box size="0.030 0.025 0.045"/></geometry><origin xyz="0 0 0.0225"/></collision>
    <inertial><mass value="0.05"/><origin xyz="0 0 0.0225"/>
      <inertia ixx="0.00005" ixy="0" ixz="0" iyy="0.00005" iyz="0" izz="0.00005"/></inertial>
  </link>
  <joint name="wrist_joint_r" type="revolute">
    <parent link="forearm_r"/><child link="wrist_r"/>
    <origin xyz="0 0 0.095"/><axis xyz="0 0 -1"/>
    <limit lower="-1.5708" upper="1.5708" effort="5" velocity="1.0"/>
  </joint>

  <!-- ======== GRIPPER JOINT ======== -->

  <link name="gripper_base_l">
    <inertial><mass value="0.005"/>
      <inertia ixx="0.000001" ixy="0" ixz="0" iyy="0.000001" iyz="0" izz="0.000001"/></inertial>
  </link>
  <joint name="gripper_base_joint_l" type="fixed">
    <parent link="wrist_l"/><child link="gripper_base_l"/>
    <origin xyz="0 0 0.045"/>
  </joint>

  <link name="gripper_left_l">
    <visual><geometry><box size="0.004 0.010 0.055"/></geometry>
      <origin xyz="0 0 0.0275"/><material name="green"/></visual>
    <visual><geometry><box size="0.004 0.010 0.012"/></geometry>
      <origin xyz="0.003 0 0.055" rpy="0 -0.3 0"/><material name="green"/></visual>
    <collision><geometry><box size="0.010 0.012 0.062"/></geometry><origin xyz="0.002 0 0.031"/></collision>
    <inertial><mass value="0.01"/><origin xyz="0 0 0.030"/>
      <inertia ixx="0.000005" ixy="0" ixz="0" iyy="0.000005" iyz="0" izz="0.000002"/></inertial>
  </link>
  <joint name="gripper_joint_l" type="revolute">
    <parent link="gripper_base_l"/><child link="gripper_left_l"/>
    <origin xyz="-0.008 0 0"/><axis xyz="0 -1 0"/>
    <limit lower="0" upper="0.5" effort="2" velocity="1.0"/>
  </joint>

  <link name="gripper_base_r">
    <inertial><mass value="0.005"/>
      <inertia ixx="0.000001" ixy="0" ixz="0" iyy="0.000001" iyz="0" izz="0.000001"/></inertial>
  </link>
  <joint name="gripper_base_joint_r" type="fixed">
    <parent link="wrist_r"/><child link="gripper_base_r"/>
    <origin xyz="0 0 0.045"/>
  </joint>

  <link name="gripper_left_r">
    <visual><geometry><box size="0.004 0.010 0.055"/></geometry>
      <origin xyz="0 0 0.0275"/><material name="green"/></visual>
    <visual><geometry><box size="0.004 0.010 0.012"/></geometry>
      <origin xyz="0.003 0 0.055" rpy="0 -0.3 0"/><material name="green"/></visual>
    <collision><geometry><box size="0.010 0.012 0.062"/></geometry><origin xyz="0.002 0 0.031"/></collision>
    <inertial><mass value="0.01"/><origin xyz="0 0 0.030"/>
      <inertia ixx="0.000005" ixy="0" ixz="0" iyy="0.000005" iyz="0" izz="0.000002"/></inertial>
  </link>
  <joint name="gripper_joint_r" type="revolute">
    <parent link="gripper_base_r"/><child link="gripper_left_r"/>
    <origin xyz="-0.008 0 0"/><axis xyz="0 -1 0"/>
    <limit lower="0" upper="0.5" effort="2" velocity="1.0"/>
  </joint>

  <!-- ======== GRIPPER RIGHT (mimic, fixed) ======== -->

  <link name="gripper_right_l">
    <visual><geometry><box size="0.004 0.010 0.055"/></geometry>
      <origin xyz="0 0 0.0275"/><material name="green"/></visual>
    <visual><geometry><box size="0.004 0.010 0.012"/></geometry>
      <origin xyz="-0.003 0 0.055" rpy="0 0.3 0"/><material name="green"/></visual>
    <collision><geometry><box size="0.010 0.012 0.062"/></geometry><origin xyz="-0.002 0 0.031"/></collision>
    <inertial><mass value="0.01"/><origin xyz="0 0 0.030"/>
      <inertia ixx="0.000005" ixy="0" ixz="0" iyy="0.000005" iyz="0" izz="0.000002"/></inertial>
  </link>
  <joint name="gripper_right_joint_l" type="revolute">
    <parent link="gripper_base_l"/><child link="gripper_right_l"/>
    <origin xyz="0.008 0 0"/><axis xyz="0 1 0"/>
    <limit lower="0" upper="0.5" effort="2" velocity="1.0"/>
    <mimic joint="gripper_joint_l" multiplier="1.0" offset="0"/>
  </joint>

  <link name="gripper_right_r">
    <visual><geometry><box size="0.004 0.010 0.055"/></geometry>
      <origin xyz="0 0 0.0275"/><material name="green"/></visual>
    <visual><geometry><box size="0.004 0.010 0.012"/></geometry>
      <origin xyz="-0.003 0 0.055" rpy="0 0.3 0"/><material name="green"/></visual>
    <collision><geometry><box size="0.010 0.012 0.062"/></geometry><origin xyz="-0.002 0 0.031"/></collision>
    <inertial><mass value="0.01"/><origin xyz="0 0 0.030"/>
      <inertia ixx="0.000005" ixy="0" ixz="0" iyy="0.000005" iyz="0" izz="0.000002"/></inertial>
  </link>
  <joint name="gripper_right_joint_r" type="revolute">
    <parent link="gripper_base_r"/><child link="gripper_right_r"/>
    <origin xyz="0.008 0 0"/><axis xyz="0 1 0"/>
    <limit lower="0" upper="0.5" effort="2" velocity="1.0"/>
    <mimic joint="gripper_joint_r" multiplier="1.0" offset="0"/>
  </joint>

</robot>
